[2025-08-11 17:00:00,123] {taskinstance.py:876} ERROR - Task failed with exception
Traceback (most recent call last):
  File "/usr/local/airflow/dags/failing_dag.py", line 52, in _transform
    num_items = len(data['items'])  # <-- Failure point
TypeError: 'NoneType' object is not subscriptable

During handling of the above exception, another exception occurred:

Traceback (most recent call last):
  File "/usr/local/airflow/utils/session.py", line 79, in wrapper
    ret = func(*args, **kwargs)
  File "/usr/local/airflow/models/taskinstance.py", line 1217, in _run_raw_task
    result = task_copy.execute(context)
  File "/usr/local/airflow/operators/python.py", line 189, in execute
    return self.execute_callable()
  File "/usr/local/airflow/operators/python.py", line 202, in execute_callable
    return self.python_callable(*self.op_args, **self.op_kwargs)
  File "/usr/local/airflow/dags/failing_dag.py", line 54, in _transform
    raise
  File "/usr/local/airflow/dags/failing_dag.py", line 52, in _transform
    num_items = len(data['items'])
TypeError: 'NoneType' object is not subscriptable

[2025-08-11 17:00:00,456] {taskinstance.py:899} INFO - Marking task as FAILED. dag_id=api_transform_dag, task_id=transform_task, execution_date=2025-08-11T17:00:00+00:00
[2025-08-11 17:00:00,457] {local_task_job.py:151} INFO - Task exited with return code 1
